<?xml version="1.0" encoding="utf-8"?>
<!--
  CR20 Robot - URDF para NVIDIA Isaac Sim
  - SIN world link
  - SIN dummy_link
  - Damping reducido
  - base_link es el ROOT
-->
<robot name="cr20_robot">

  <!-- ========== BASE LINK (ROOT) ========== -->
  <link name="base_link">
    <inertial>
      <origin xyz="-0.0523349568972135 0.0899270486094572 -0.00279275668479641" rpy="0 0 0"/>
      <mass value="5.0"/>
      <inertia ixx="0.01" ixy="0.0" ixz="0.0"
                          iyy="0.01" iyz="0.0"
                                     izz="0.01"/>
    </inertial>
    <visual>
      <origin xyz="0 0 0" rpy="0 0 0"/>
      <geometry>
        <mesh filename="/home/iudc/dobot_ws/src/DOBOT_6Axis_ROS2_V4/cra_description/meshes/cr20/base_link.STL"/>
      </geometry>
      <material name="robot_blue">
        <color rgba="0.792156862745098 0.819607843137255 0.933333333333333 1"/>
      </material>
    </visual>
    <collision>
      <origin xyz="0 0 0" rpy="0 0 0"/>
      <geometry>
        <mesh filename="/home/iudc/dobot_ws/src/DOBOT_6Axis_ROS2_V4/cra_description/meshes/cr20/base_link.STL"/>
      </geometry>
    </collision>
  </link>

  <!-- ========== LINK 1 ========== -->
  <link name="Link1">
    <inertial>
      <origin xyz="-0.0154576425326206 -0.0986375365415087 1.04119647925812" rpy="0 0 0"/>
      <mass value="8.0"/>
      <inertia ixx="0.05" ixy="0.0" ixz="0.0"
                          iyy="0.05" iyz="0.0"
                                     izz="0.02"/>
    </inertial>
    <visual>
      <origin xyz="0 0 0" rpy="0 0 0"/>
      <geometry>
        <mesh filename="/home/iudc/dobot_ws/src/DOBOT_6Axis_ROS2_V4/cra_description/meshes/cr20/Link1.STL"/>
      </geometry>
      <material name="robot_blue"/>
    </visual>
    <collision>
      <origin xyz="0 0 0" rpy="0 0 0"/>
      <geometry>
        <mesh filename="/home/iudc/dobot_ws/src/DOBOT_6Axis_ROS2_V4/cra_description/meshes/cr20/Link1.STL"/>
      </geometry>
    </collision>
  </link>

  <joint name="joint1" type="revolute">
    <origin xyz="0 0 0.23" rpy="0 0 0"/>
    <parent link="base_link"/>
    <child  link="Link1"/>
    <axis xyz="0 0 1"/>
    <limit lower="-6.28" upper="6.28" effort="150" velocity="3.14"/>
    <dynamics damping="0.5" friction="0.1"/>
  </joint>

  <!-- ========== LINK 2 ========== -->
  <link name="Link2">
    <inertial>
      <origin xyz="-0.828898669983325 -3.97165169431493E-07 0.115283168336158" rpy="0 0 0"/>
      <mass value="6.0"/>
      <inertia ixx="0.1"  ixy="0.0" ixz="0.0"
                          iyy="0.1"  iyz="0.0"
                                     izz="0.02"/>
    </inertial>
    <visual>
      <origin xyz="0 0 0" rpy="0 0 0"/>
      <geometry>
        <mesh filename="/home/iudc/dobot_ws/src/DOBOT_6Axis_ROS2_V4/cra_description/meshes/cr20/Link2.STL"/>
      </geometry>
      <material name="robot_blue"/>
    </visual>
    <collision>
      <origin xyz="0 0 0" rpy="0 0 0"/>
      <geometry>
        <mesh filename="/home/iudc/dobot_ws/src/DOBOT_6Axis_ROS2_V4/cra_description/meshes/cr20/Link2.STL"/>
      </geometry>
    </collision>
  </link>

  <joint name="joint2" type="revolute">
    <origin xyz="0 0 0" rpy="1.5708 1.5708 0"/>
    <parent link="Link1"/>
    <child  link="Link2"/>
    <axis xyz="0 0 1"/>
    <limit lower="-6.28" upper="6.28" effort="150" velocity="3.14"/>
    <dynamics damping="0.5" friction="0.1"/>
  </joint>

  <!-- ========== LINK 3 ========== -->
  <link name="Link3">
    <inertial>
      <origin xyz="-0.746000007821945 1.07337005127015E-07 0.0757301295800403" rpy="0 0 0"/>
      <mass value="4.0"/>
      <inertia ixx="0.05" ixy="0.0" ixz="0.0"
                          iyy="0.05" iyz="0.0"
                                     izz="0.01"/>
    </inertial>
    <visual>
      <origin xyz="0 0 0" rpy="0 0 0"/>
      <geometry>
        <mesh filename="/home/iudc/dobot_ws/src/DOBOT_6Axis_ROS2_V4/cra_description/meshes/cr20/Link3.STL"/>
      </geometry>
      <material name="robot_blue"/>
    </visual>
    <collision>
      <origin xyz="0 0 0" rpy="0 0 0"/>
      <geometry>
        <mesh filename="/home/iudc/dobot_ws/src/DOBOT_6Axis_ROS2_V4/cra_description/meshes/cr20/Link3.STL"/>
      </geometry>
    </collision>
  </link>

  <joint name="joint3" type="revolute">
    <origin xyz="-0.8252 0 0.0468" rpy="0 0 0"/>
    <parent link="Link2"/>
    <child  link="Link3"/>
    <axis xyz="0 0 1"/>
    <limit lower="-2.9" upper="2.9" effort="150" velocity="3.14"/>
    <dynamics damping="0.3" friction="0.1"/>
  </joint>

  <!-- ========== LINK 4 ========== -->
  <link name="Link4">
    <inertial>
      <origin xyz="1.09076486456641E-07 -0.0757301256894509 1.20551504334543E-08" rpy="0 0 0"/>
      <mass value="3.0"/>
      <inertia ixx="0.01"  ixy="0.0" ixz="0.0"
                           iyy="0.01"  iyz="0.0"
                                       izz="0.005"/>
    </inertial>
    <visual>
      <origin xyz="0 0 0" rpy="0 0 0"/>
      <geometry>
        <mesh filename="/home/iudc/dobot_ws/src/DOBOT_6Axis_ROS2_V4/cra_description/meshes/cr20/Link4.STL"/>
      </geometry>
      <material name="robot_blue"/>
    </visual>
    <collision>
      <origin xyz="0 0 0" rpy="0 0 0"/>
      <geometry>
        <mesh filename="/home/iudc/dobot_ws/src/DOBOT_6Axis_ROS2_V4/cra_description/meshes/cr20/Link4.STL"/>
      </geometry>
    </collision>
  </link>

  <joint name="joint4" type="revolute">
    <origin xyz="-0.746 0 0.1288" rpy="0 0 -1.5708"/>
    <parent link="Link3"/>
    <child  link="Link4"/>
    <axis xyz="0 0 1"/>
    <limit lower="-6.28" upper="6.28" effort="50" velocity="3.14"/>
    <dynamics damping="0.2" friction="0.05"/>
  </joint>

  <!-- ========== LINK 5 ========== -->
  <link name="Link5">
    <inertial>
      <origin xyz="-1.06334234349293E-07 0.075730132822537 4.0368623999143E-09" rpy="0 0 0"/>
      <mass value="2.0"/>
      <inertia ixx="0.005" ixy="0.0" ixz="0.0"
                           iyy="0.005" iyz="0.0"
                                       izz="0.003"/>
    </inertial>
    <visual>
      <origin xyz="0 0 0" rpy="0 0 0"/>
      <geometry>
        <mesh filename="/home/iudc/dobot_ws/src/DOBOT_6Axis_ROS2_V4/cra_description/meshes/cr20/Link5.STL"/>
      </geometry>
      <material name="robot_blue"/>
    </visual>
    <collision>
      <origin xyz="0 0 0" rpy="0 0 0"/>
      <geometry>
        <mesh filename="/home/iudc/dobot_ws/src/DOBOT_6Axis_ROS2_V4/cra_description/meshes/cr20/Link5.STL"/>
      </geometry>
    </collision>
  </link>

  <joint name="joint5" type="revolute">
    <origin xyz="0 -0.1288 0" rpy="1.5708 0 0"/>
    <parent link="Link4"/>
    <child  link="Link5"/>
    <axis xyz="0 0 1"/>
    <limit lower="-6.28" upper="6.28" effort="50" velocity="3.14"/>
    <dynamics damping="0.1" friction="0.05"/>
  </joint>

  <!-- ========== LINK 6 ========== -->
  <link name="Link6">
    <inertial>
      <origin xyz="0.0154576401891996 0.658802608062882 -0.213462466800391" rpy="0 0 0"/>
      <mass value="1.0"/>
      <inertia ixx="0.002" ixy="0.0" ixz="0.0"
                           iyy="0.002" iyz="0.0"
                                       izz="0.001"/>
    </inertial>
    <visual>
      <origin xyz="0 0 0" rpy="0 0 0"/>
      <geometry>
        <mesh filename="/home/iudc/dobot_ws/src/DOBOT_6Axis_ROS2_V4/cra_description/meshes/cr20/Link6.STL"/>
      </geometry>
      <material name="robot_blue"/>
    </visual>
    <collision>
      <origin xyz="0 0 0" rpy="0 0 0"/>
      <geometry>
        <mesh filename="/home/iudc/dobot_ws/src/DOBOT_6Axis_ROS2_V4/cra_description/meshes/cr20/Link6.STL"/>
      </geometry>
    </collision>
  </link>

  <joint name="joint6" type="revolute">
    <origin xyz="0 0.1365 0" rpy="-1.5708 0 0"/>
    <parent link="Link5"/>
    <child  link="Link6"/>
    <axis xyz="0 0 1"/>
    <limit lower="-6.28" upper="6.28" effort="50" velocity="3.14"/>
    <dynamics damping="0.1" friction="0.05"/>
  </joint>

  <!-- ========== GRIPPER DE VENTOSAS ========== -->
  <link name="gripper_link">
      <inertial>
        <origin xyz="0 0 0.05" rpy="0 0 0"/>
        <mass value="0.5"/>
        <inertia ixx="0.001" ixy="0.0" ixz="0.0"
                iyy="0.001" iyz="0.0"
                izz="0.001"/>
      </inertial>
      <visual>
        <origin xyz="0 0 0" rpy="0 0 0"/>
        <geometry>
          <mesh filename="/home/iudc/dobot_ws/src/DOBOT_6Axis_ROS2_V4/cra_description/meshes/cr20/gripper_link.stl"/>
        </geometry>
        <material name="gripper_material">
          <color rgba="0.2 0.2 0.2 1"/>
        </material>
      </visual>
      <collision>
        <origin xyz="0 0 0" rpy="0 0 0"/>
        <geometry>
          <mesh filename="/home/iudc/dobot_ws/src/DOBOT_6Axis_ROS2_V4/cra_description/meshes/cr20/gripper_link.stl"/>
        </geometry>
      </collision>
    </link>

    <!-- FIXED = pegado a Link6, no se mueve solo -->
    <joint name="gripper_joint" type="fixed">
      <origin xyz="0 0 0" rpy="0 0 0"/>
      <parent link="Link6"/>
      <child link="gripper_link"/>
    </joint>

</robot>